2025-01-28 11:32:21,632 [DEBUG] base: Asynchronous handler adapted for middleware whitenoise.middleware.WhiteNoiseMiddleware.
2025-01-28 11:40:38,288 [DEBUG] base: Asynchronous handler adapted for middleware whitenoise.middleware.WhiteNoiseMiddleware.
2025-01-28 11:44:23,939 [DEBUG] base: Asynchronous handler adapted for middleware whitenoise.middleware.WhiteNoiseMiddleware.
2025-01-28 11:44:35,125 [DEBUG] base: Exception while resolving variable 'name' in template 'unknown'.
Traceback (most recent call last):
  File "/Users/corentindremaux/fablab_project/venv/lib/python3.11/site-packages/asgiref/sync.py", line 518, in thread_handler
    raise exc_info[1]
  File "/Users/corentindremaux/fablab_project/venv/lib/python3.11/site-packages/django/core/handlers/exception.py", line 42, in inner
    response = await get_response(request)
               ^^^^^^^^^^^^^^^^^^^^^^^^^^^
  File "/Users/corentindremaux/fablab_project/venv/lib/python3.11/site-packages/django/core/handlers/base.py", line 235, in _get_response_async
    callback, callback_args, callback_kwargs = self.resolve_request(request)
                                               ^^^^^^^^^^^^^^^^^^^^^^^^^^^^^
  File "/Users/corentindremaux/fablab_project/venv/lib/python3.11/site-packages/django/core/handlers/base.py", line 313, in resolve_request
    resolver_match = resolver.resolve(request.path_info)
                     ^^^^^^^^^^^^^^^^^^^^^^^^^^^^^^^^^^^
  File "/Users/corentindremaux/fablab_project/venv/lib/python3.11/site-packages/django/urls/resolvers.py", line 705, in resolve
    raise Resolver404({"tried": tried, "path": new_path})
django.urls.exceptions.Resolver404: {'tried': [[<URLResolver <URLPattern list> (admin:admin) 'admin/'>], [<URLResolver <URLPattern list> (None:None) 'api/'>], [<URLPattern 'api/stock/' [name='stock']>], [<URLPattern '^static/(?P<path>.*)$'>]], 'path': ''}

During handling of the above exception, another exception occurred:

Traceback (most recent call last):
  File "/Users/corentindremaux/fablab_project/venv/lib/python3.11/site-packages/django/template/base.py", line 883, in _resolve_lookup
    current = current[bit]
              ~~~~~~~^^^^^
TypeError: 'URLResolver' object is not subscriptable

During handling of the above exception, another exception occurred:

Traceback (most recent call last):
  File "/Users/corentindremaux/fablab_project/venv/lib/python3.11/site-packages/django/template/base.py", line 893, in _resolve_lookup
    current = getattr(current, bit)
              ^^^^^^^^^^^^^^^^^^^^^
AttributeError: 'URLResolver' object has no attribute 'name'

During handling of the above exception, another exception occurred:

Traceback (most recent call last):
  File "/Users/corentindremaux/fablab_project/venv/lib/python3.11/site-packages/django/template/base.py", line 899, in _resolve_lookup
    current = current[int(bit)]
                      ^^^^^^^^
ValueError: invalid literal for int() with base 10: 'name'

During handling of the above exception, another exception occurred:

Traceback (most recent call last):
  File "/Users/corentindremaux/fablab_project/venv/lib/python3.11/site-packages/django/template/base.py", line 906, in _resolve_lookup
    raise VariableDoesNotExist(
django.template.base.VariableDoesNotExist: Failed lookup for key [name] in <URLResolver <URLPattern list> (admin:admin) 'admin/'>
2025-01-28 11:44:35,134 [DEBUG] base: Exception while resolving variable 'name' in template 'unknown'.
Traceback (most recent call last):
  File "/Users/corentindremaux/fablab_project/venv/lib/python3.11/site-packages/asgiref/sync.py", line 518, in thread_handler
    raise exc_info[1]
  File "/Users/corentindremaux/fablab_project/venv/lib/python3.11/site-packages/django/core/handlers/exception.py", line 42, in inner
    response = await get_response(request)
               ^^^^^^^^^^^^^^^^^^^^^^^^^^^
  File "/Users/corentindremaux/fablab_project/venv/lib/python3.11/site-packages/django/core/handlers/base.py", line 235, in _get_response_async
    callback, callback_args, callback_kwargs = self.resolve_request(request)
                                               ^^^^^^^^^^^^^^^^^^^^^^^^^^^^^
  File "/Users/corentindremaux/fablab_project/venv/lib/python3.11/site-packages/django/core/handlers/base.py", line 313, in resolve_request
    resolver_match = resolver.resolve(request.path_info)
                     ^^^^^^^^^^^^^^^^^^^^^^^^^^^^^^^^^^^
  File "/Users/corentindremaux/fablab_project/venv/lib/python3.11/site-packages/django/urls/resolvers.py", line 705, in resolve
    raise Resolver404({"tried": tried, "path": new_path})
django.urls.exceptions.Resolver404: {'tried': [[<URLResolver <URLPattern list> (admin:admin) 'admin/'>], [<URLResolver <URLPattern list> (None:None) 'api/'>], [<URLPattern 'api/stock/' [name='stock']>], [<URLPattern '^static/(?P<path>.*)$'>]], 'path': ''}

During handling of the above exception, another exception occurred:

Traceback (most recent call last):
  File "/Users/corentindremaux/fablab_project/venv/lib/python3.11/site-packages/django/template/base.py", line 883, in _resolve_lookup
    current = current[bit]
              ~~~~~~~^^^^^
TypeError: 'URLResolver' object is not subscriptable

During handling of the above exception, another exception occurred:

Traceback (most recent call last):
  File "/Users/corentindremaux/fablab_project/venv/lib/python3.11/site-packages/django/template/base.py", line 893, in _resolve_lookup
    current = getattr(current, bit)
              ^^^^^^^^^^^^^^^^^^^^^
AttributeError: 'URLResolver' object has no attribute 'name'

During handling of the above exception, another exception occurred:

Traceback (most recent call last):
  File "/Users/corentindremaux/fablab_project/venv/lib/python3.11/site-packages/django/template/base.py", line 899, in _resolve_lookup
    current = current[int(bit)]
                      ^^^^^^^^
ValueError: invalid literal for int() with base 10: 'name'

During handling of the above exception, another exception occurred:

Traceback (most recent call last):
  File "/Users/corentindremaux/fablab_project/venv/lib/python3.11/site-packages/django/template/base.py", line 906, in _resolve_lookup
    raise VariableDoesNotExist(
django.template.base.VariableDoesNotExist: Failed lookup for key [name] in <URLResolver <URLPattern list> (None:None) 'api/'>
2025-01-28 11:44:35,137 [WARNING] log: Not Found: /
2025-01-28 11:44:41,412 [DEBUG] base: Exception while resolving variable 'name' in template 'unknown'.
Traceback (most recent call last):
  File "/Users/corentindremaux/fablab_project/venv/lib/python3.11/site-packages/asgiref/sync.py", line 518, in thread_handler
    raise exc_info[1]
  File "/Users/corentindremaux/fablab_project/venv/lib/python3.11/site-packages/django/core/handlers/exception.py", line 42, in inner
    response = await get_response(request)
               ^^^^^^^^^^^^^^^^^^^^^^^^^^^
  File "/Users/corentindremaux/fablab_project/venv/lib/python3.11/site-packages/django/core/handlers/base.py", line 235, in _get_response_async
    callback, callback_args, callback_kwargs = self.resolve_request(request)
                                               ^^^^^^^^^^^^^^^^^^^^^^^^^^^^^
  File "/Users/corentindremaux/fablab_project/venv/lib/python3.11/site-packages/django/core/handlers/base.py", line 313, in resolve_request
    resolver_match = resolver.resolve(request.path_info)
                     ^^^^^^^^^^^^^^^^^^^^^^^^^^^^^^^^^^^
  File "/Users/corentindremaux/fablab_project/venv/lib/python3.11/site-packages/django/urls/resolvers.py", line 705, in resolve
    raise Resolver404({"tried": tried, "path": new_path})
django.urls.exceptions.Resolver404: {'tried': [[<URLResolver <URLPattern list> (admin:admin) 'admin/'>], [<URLResolver <URLPattern list> (None:None) 'api/'>], [<URLPattern 'api/stock/' [name='stock']>], [<URLPattern '^static/(?P<path>.*)$'>]], 'path': 'admin'}

During handling of the above exception, another exception occurred:

Traceback (most recent call last):
  File "/Users/corentindremaux/fablab_project/venv/lib/python3.11/site-packages/django/template/base.py", line 883, in _resolve_lookup
    current = current[bit]
              ~~~~~~~^^^^^
TypeError: 'URLResolver' object is not subscriptable

During handling of the above exception, another exception occurred:

Traceback (most recent call last):
  File "/Users/corentindremaux/fablab_project/venv/lib/python3.11/site-packages/django/template/base.py", line 893, in _resolve_lookup
    current = getattr(current, bit)
              ^^^^^^^^^^^^^^^^^^^^^
AttributeError: 'URLResolver' object has no attribute 'name'

During handling of the above exception, another exception occurred:

Traceback (most recent call last):
  File "/Users/corentindremaux/fablab_project/venv/lib/python3.11/site-packages/django/template/base.py", line 899, in _resolve_lookup
    current = current[int(bit)]
                      ^^^^^^^^
ValueError: invalid literal for int() with base 10: 'name'

During handling of the above exception, another exception occurred:

Traceback (most recent call last):
  File "/Users/corentindremaux/fablab_project/venv/lib/python3.11/site-packages/django/template/base.py", line 906, in _resolve_lookup
    raise VariableDoesNotExist(
django.template.base.VariableDoesNotExist: Failed lookup for key [name] in <URLResolver <URLPattern list> (admin:admin) 'admin/'>
2025-01-28 11:44:41,413 [DEBUG] base: Exception while resolving variable 'name' in template 'unknown'.
Traceback (most recent call last):
  File "/Users/corentindremaux/fablab_project/venv/lib/python3.11/site-packages/asgiref/sync.py", line 518, in thread_handler
    raise exc_info[1]
  File "/Users/corentindremaux/fablab_project/venv/lib/python3.11/site-packages/django/core/handlers/exception.py", line 42, in inner
    response = await get_response(request)
               ^^^^^^^^^^^^^^^^^^^^^^^^^^^
  File "/Users/corentindremaux/fablab_project/venv/lib/python3.11/site-packages/django/core/handlers/base.py", line 235, in _get_response_async
    callback, callback_args, callback_kwargs = self.resolve_request(request)
                                               ^^^^^^^^^^^^^^^^^^^^^^^^^^^^^
  File "/Users/corentindremaux/fablab_project/venv/lib/python3.11/site-packages/django/core/handlers/base.py", line 313, in resolve_request
    resolver_match = resolver.resolve(request.path_info)
                     ^^^^^^^^^^^^^^^^^^^^^^^^^^^^^^^^^^^
  File "/Users/corentindremaux/fablab_project/venv/lib/python3.11/site-packages/django/urls/resolvers.py", line 705, in resolve
    raise Resolver404({"tried": tried, "path": new_path})
django.urls.exceptions.Resolver404: {'tried': [[<URLResolver <URLPattern list> (admin:admin) 'admin/'>], [<URLResolver <URLPattern list> (None:None) 'api/'>], [<URLPattern 'api/stock/' [name='stock']>], [<URLPattern '^static/(?P<path>.*)$'>]], 'path': 'admin'}

During handling of the above exception, another exception occurred:

Traceback (most recent call last):
  File "/Users/corentindremaux/fablab_project/venv/lib/python3.11/site-packages/django/template/base.py", line 883, in _resolve_lookup
    current = current[bit]
              ~~~~~~~^^^^^
TypeError: 'URLResolver' object is not subscriptable

During handling of the above exception, another exception occurred:

Traceback (most recent call last):
  File "/Users/corentindremaux/fablab_project/venv/lib/python3.11/site-packages/django/template/base.py", line 893, in _resolve_lookup
    current = getattr(current, bit)
              ^^^^^^^^^^^^^^^^^^^^^
AttributeError: 'URLResolver' object has no attribute 'name'

During handling of the above exception, another exception occurred:

Traceback (most recent call last):
  File "/Users/corentindremaux/fablab_project/venv/lib/python3.11/site-packages/django/template/base.py", line 899, in _resolve_lookup
    current = current[int(bit)]
                      ^^^^^^^^
ValueError: invalid literal for int() with base 10: 'name'

During handling of the above exception, another exception occurred:

Traceback (most recent call last):
  File "/Users/corentindremaux/fablab_project/venv/lib/python3.11/site-packages/django/template/base.py", line 906, in _resolve_lookup
    raise VariableDoesNotExist(
django.template.base.VariableDoesNotExist: Failed lookup for key [name] in <URLResolver <URLPattern list> (None:None) 'api/'>
2025-01-28 11:44:53,911 [DEBUG] utils: (0.002) SELECT "auth_user"."id", "auth_user"."password", "auth_user"."last_login", "auth_user"."is_superuser", "auth_user"."username", "auth_user"."first_name", "auth_user"."last_name", "auth_user"."email", "auth_user"."is_staff", "auth_user"."is_active", "auth_user"."date_joined" FROM "auth_user" WHERE "auth_user"."username" = 'webtech' LIMIT 21; args=('webtech',); alias=default
2025-01-28 11:44:54,561 [DEBUG] utils: (0.000) SELECT 1 AS "a" FROM "django_session" WHERE "django_session"."session_key" = 'fwpq37u49j36oj3xtwrkhy7bf34wzur2' LIMIT 1; args=(1, 'fwpq37u49j36oj3xtwrkhy7bf34wzur2'); alias=default
2025-01-28 11:44:54,563 [DEBUG] utils: (0.000) BEGIN; args=None; alias=default
2025-01-28 11:44:54,565 [DEBUG] utils: (0.001) INSERT INTO "django_session" ("session_key", "session_data", "expire_date") VALUES ('fwpq37u49j36oj3xtwrkhy7bf34wzur2', 'e30:1tck1W:zlW16GbYaPM6yROlRCHn2Bt2HVeOZb5fU6k8gFu4EwE', '2025-02-11 11:44:54.562626'); args=('fwpq37u49j36oj3xtwrkhy7bf34wzur2', 'e30:1tck1W:zlW16GbYaPM6yROlRCHn2Bt2HVeOZb5fU6k8gFu4EwE', '2025-02-11 11:44:54.562626'); alias=default
2025-01-28 11:44:54,566 [DEBUG] utils: (0.001) COMMIT; args=None; alias=default
2025-01-28 11:44:54,569 [DEBUG] utils: (0.001) UPDATE "auth_user" SET "last_login" = '2025-01-28 11:44:54.567186' WHERE "auth_user"."id" = 1; args=('2025-01-28 11:44:54.567186', 1); alias=default
2025-01-28 11:44:54,570 [DEBUG] utils: (0.000) BEGIN; args=None; alias=default
2025-01-28 11:44:54,571 [DEBUG] utils: (0.000) UPDATE "django_session" SET "session_data" = '.eJxVjEEOwiAQRe_C2hBoYUZcuu8ZyACDVA0kpV0Z765NutDtf-_9l_C0rcVvnRc_J3ERWpx-t0DxwXUH6U711mRsdV3mIHdFHrTLqSV-Xg_376BQL9-aLFgdEuUYIKrRZRyQlTMGrDsbNAPwmI0jAKWQtcohYR4hWEbNEVm8P9lVN7Q:1tck1W:LKB6F-cK_L34imZdd9urFfM0T25CVy-ZAVCQRrtkSWY', "expire_date" = '2025-02-11 11:44:54.570719' WHERE "django_session"."session_key" = 'fwpq37u49j36oj3xtwrkhy7bf34wzur2'; args=('.eJxVjEEOwiAQRe_C2hBoYUZcuu8ZyACDVA0kpV0Z765NutDtf-_9l_C0rcVvnRc_J3ERWpx-t0DxwXUH6U711mRsdV3mIHdFHrTLqSV-Xg_376BQL9-aLFgdEuUYIKrRZRyQlTMGrDsbNAPwmI0jAKWQtcohYR4hWEbNEVm8P9lVN7Q:1tck1W:LKB6F-cK_L34imZdd9urFfM0T25CVy-ZAVCQRrtkSWY', '2025-02-11 11:44:54.570719', 'fwpq37u49j36oj3xtwrkhy7bf34wzur2'); alias=default
2025-01-28 11:44:54,572 [DEBUG] utils: (0.001) COMMIT; args=None; alias=default
2025-01-28 11:44:54,579 [DEBUG] utils: (0.000) SELECT "django_session"."session_key", "django_session"."session_data", "django_session"."expire_date" FROM "django_session" WHERE ("django_session"."expire_date" > '2025-01-28 11:44:54.578086' AND "django_session"."session_key" = 'fwpq37u49j36oj3xtwrkhy7bf34wzur2') LIMIT 21; args=('2025-01-28 11:44:54.578086', 'fwpq37u49j36oj3xtwrkhy7bf34wzur2'); alias=default
2025-01-28 11:44:54,580 [DEBUG] utils: (0.000) SELECT "auth_user"."id", "auth_user"."password", "auth_user"."last_login", "auth_user"."is_superuser", "auth_user"."username", "auth_user"."first_name", "auth_user"."last_name", "auth_user"."email", "auth_user"."is_staff", "auth_user"."is_active", "auth_user"."date_joined" FROM "auth_user" WHERE "auth_user"."id" = 1 LIMIT 21; args=(1,); alias=default
2025-01-28 11:44:54,594 [DEBUG] utils: (0.002) SELECT "django_admin_log"."id", "django_admin_log"."action_time", "django_admin_log"."user_id", "django_admin_log"."content_type_id", "django_admin_log"."object_id", "django_admin_log"."object_repr", "django_admin_log"."action_flag", "django_admin_log"."change_message", "auth_user"."id", "auth_user"."password", "auth_user"."last_login", "auth_user"."is_superuser", "auth_user"."username", "auth_user"."first_name", "auth_user"."last_name", "auth_user"."email", "auth_user"."is_staff", "auth_user"."is_active", "auth_user"."date_joined", "django_content_type"."id", "django_content_type"."app_label", "django_content_type"."model" FROM "django_admin_log" INNER JOIN "auth_user" ON ("django_admin_log"."user_id" = "auth_user"."id") LEFT OUTER JOIN "django_content_type" ON ("django_admin_log"."content_type_id" = "django_content_type"."id") WHERE "django_admin_log"."user_id" = 1 ORDER BY "django_admin_log"."action_time" DESC LIMIT 10; args=(1,); alias=default
2025-01-28 11:53:41,136 [DEBUG] base: Asynchronous handler adapted for middleware whitenoise.middleware.WhiteNoiseMiddleware.
2025-01-28 11:53:54,882 [DEBUG] base: Exception while resolving variable 'name' in template 'unknown'.
Traceback (most recent call last):
  File "/Users/corentindremaux/fablab_project/venv/lib/python3.11/site-packages/asgiref/sync.py", line 518, in thread_handler
    raise exc_info[1]
  File "/Users/corentindremaux/fablab_project/venv/lib/python3.11/site-packages/django/core/handlers/exception.py", line 42, in inner
    response = await get_response(request)
               ^^^^^^^^^^^^^^^^^^^^^^^^^^^
  File "/Users/corentindremaux/fablab_project/venv/lib/python3.11/site-packages/django/core/handlers/base.py", line 235, in _get_response_async
    callback, callback_args, callback_kwargs = self.resolve_request(request)
                                               ^^^^^^^^^^^^^^^^^^^^^^^^^^^^^
  File "/Users/corentindremaux/fablab_project/venv/lib/python3.11/site-packages/django/core/handlers/base.py", line 313, in resolve_request
    resolver_match = resolver.resolve(request.path_info)
                     ^^^^^^^^^^^^^^^^^^^^^^^^^^^^^^^^^^^
  File "/Users/corentindremaux/fablab_project/venv/lib/python3.11/site-packages/django/urls/resolvers.py", line 705, in resolve
    raise Resolver404({"tried": tried, "path": new_path})
django.urls.exceptions.Resolver404: {'tried': [[<URLResolver <URLPattern list> (admin:admin) 'admin/'>], [<URLResolver <URLPattern list> (None:None) 'api/'>], [<URLPattern 'api/stock/' [name='stock']>], [<URLPattern '^static/(?P<path>.*)$'>]], 'path': ''}

During handling of the above exception, another exception occurred:

Traceback (most recent call last):
  File "/Users/corentindremaux/fablab_project/venv/lib/python3.11/site-packages/django/template/base.py", line 883, in _resolve_lookup
    current = current[bit]
              ~~~~~~~^^^^^
TypeError: 'URLResolver' object is not subscriptable

During handling of the above exception, another exception occurred:

Traceback (most recent call last):
  File "/Users/corentindremaux/fablab_project/venv/lib/python3.11/site-packages/django/template/base.py", line 893, in _resolve_lookup
    current = getattr(current, bit)
              ^^^^^^^^^^^^^^^^^^^^^
AttributeError: 'URLResolver' object has no attribute 'name'

During handling of the above exception, another exception occurred:

Traceback (most recent call last):
  File "/Users/corentindremaux/fablab_project/venv/lib/python3.11/site-packages/django/template/base.py", line 899, in _resolve_lookup
    current = current[int(bit)]
                      ^^^^^^^^
ValueError: invalid literal for int() with base 10: 'name'

During handling of the above exception, another exception occurred:

Traceback (most recent call last):
  File "/Users/corentindremaux/fablab_project/venv/lib/python3.11/site-packages/django/template/base.py", line 906, in _resolve_lookup
    raise VariableDoesNotExist(
django.template.base.VariableDoesNotExist: Failed lookup for key [name] in <URLResolver <URLPattern list> (admin:admin) 'admin/'>
2025-01-28 11:53:54,889 [DEBUG] base: Exception while resolving variable 'name' in template 'unknown'.
Traceback (most recent call last):
  File "/Users/corentindremaux/fablab_project/venv/lib/python3.11/site-packages/asgiref/sync.py", line 518, in thread_handler
    raise exc_info[1]
  File "/Users/corentindremaux/fablab_project/venv/lib/python3.11/site-packages/django/core/handlers/exception.py", line 42, in inner
    response = await get_response(request)
               ^^^^^^^^^^^^^^^^^^^^^^^^^^^
  File "/Users/corentindremaux/fablab_project/venv/lib/python3.11/site-packages/django/core/handlers/base.py", line 235, in _get_response_async
    callback, callback_args, callback_kwargs = self.resolve_request(request)
                                               ^^^^^^^^^^^^^^^^^^^^^^^^^^^^^
  File "/Users/corentindremaux/fablab_project/venv/lib/python3.11/site-packages/django/core/handlers/base.py", line 313, in resolve_request
    resolver_match = resolver.resolve(request.path_info)
                     ^^^^^^^^^^^^^^^^^^^^^^^^^^^^^^^^^^^
  File "/Users/corentindremaux/fablab_project/venv/lib/python3.11/site-packages/django/urls/resolvers.py", line 705, in resolve
    raise Resolver404({"tried": tried, "path": new_path})
django.urls.exceptions.Resolver404: {'tried': [[<URLResolver <URLPattern list> (admin:admin) 'admin/'>], [<URLResolver <URLPattern list> (None:None) 'api/'>], [<URLPattern 'api/stock/' [name='stock']>], [<URLPattern '^static/(?P<path>.*)$'>]], 'path': ''}

During handling of the above exception, another exception occurred:

Traceback (most recent call last):
  File "/Users/corentindremaux/fablab_project/venv/lib/python3.11/site-packages/django/template/base.py", line 883, in _resolve_lookup
    current = current[bit]
              ~~~~~~~^^^^^
TypeError: 'URLResolver' object is not subscriptable

During handling of the above exception, another exception occurred:

Traceback (most recent call last):
  File "/Users/corentindremaux/fablab_project/venv/lib/python3.11/site-packages/django/template/base.py", line 893, in _resolve_lookup
    current = getattr(current, bit)
              ^^^^^^^^^^^^^^^^^^^^^
AttributeError: 'URLResolver' object has no attribute 'name'

During handling of the above exception, another exception occurred:

Traceback (most recent call last):
  File "/Users/corentindremaux/fablab_project/venv/lib/python3.11/site-packages/django/template/base.py", line 899, in _resolve_lookup
    current = current[int(bit)]
                      ^^^^^^^^
ValueError: invalid literal for int() with base 10: 'name'

During handling of the above exception, another exception occurred:

Traceback (most recent call last):
  File "/Users/corentindremaux/fablab_project/venv/lib/python3.11/site-packages/django/template/base.py", line 906, in _resolve_lookup
    raise VariableDoesNotExist(
django.template.base.VariableDoesNotExist: Failed lookup for key [name] in <URLResolver <URLPattern list> (None:None) 'api/'>
2025-01-28 11:53:54,892 [WARNING] log: Not Found: /
2025-01-28 11:54:00,384 [DEBUG] utils: (0.001) SELECT "django_session"."session_key", "django_session"."session_data", "django_session"."expire_date" FROM "django_session" WHERE ("django_session"."expire_date" > '2025-01-28 11:54:00.372706' AND "django_session"."session_key" = 'fwpq37u49j36oj3xtwrkhy7bf34wzur2') LIMIT 21; args=('2025-01-28 11:54:00.372706', 'fwpq37u49j36oj3xtwrkhy7bf34wzur2'); alias=default
2025-01-28 11:54:00,386 [DEBUG] utils: (0.000) SELECT "auth_user"."id", "auth_user"."password", "auth_user"."last_login", "auth_user"."is_superuser", "auth_user"."username", "auth_user"."first_name", "auth_user"."last_name", "auth_user"."email", "auth_user"."is_staff", "auth_user"."is_active", "auth_user"."date_joined" FROM "auth_user" WHERE "auth_user"."id" = 1 LIMIT 21; args=(1,); alias=default
2025-01-28 11:54:00,436 [DEBUG] utils: (0.000) SELECT "django_admin_log"."id", "django_admin_log"."action_time", "django_admin_log"."user_id", "django_admin_log"."content_type_id", "django_admin_log"."object_id", "django_admin_log"."object_repr", "django_admin_log"."action_flag", "django_admin_log"."change_message", "auth_user"."id", "auth_user"."password", "auth_user"."last_login", "auth_user"."is_superuser", "auth_user"."username", "auth_user"."first_name", "auth_user"."last_name", "auth_user"."email", "auth_user"."is_staff", "auth_user"."is_active", "auth_user"."date_joined", "django_content_type"."id", "django_content_type"."app_label", "django_content_type"."model" FROM "django_admin_log" INNER JOIN "auth_user" ON ("django_admin_log"."user_id" = "auth_user"."id") LEFT OUTER JOIN "django_content_type" ON ("django_admin_log"."content_type_id" = "django_content_type"."id") WHERE "django_admin_log"."user_id" = 1 ORDER BY "django_admin_log"."action_time" DESC LIMIT 10; args=(1,); alias=default
2025-01-28 11:55:14,983 [DEBUG] base: Exception while resolving variable 'name' in template 'unknown'.
Traceback (most recent call last):
  File "/Users/corentindremaux/fablab_project/venv/lib/python3.11/site-packages/asgiref/sync.py", line 518, in thread_handler
    raise exc_info[1]
  File "/Users/corentindremaux/fablab_project/venv/lib/python3.11/site-packages/django/core/handlers/exception.py", line 42, in inner
    response = await get_response(request)
               ^^^^^^^^^^^^^^^^^^^^^^^^^^^
  File "/Users/corentindremaux/fablab_project/venv/lib/python3.11/site-packages/django/core/handlers/base.py", line 235, in _get_response_async
    callback, callback_args, callback_kwargs = self.resolve_request(request)
                                               ^^^^^^^^^^^^^^^^^^^^^^^^^^^^^
  File "/Users/corentindremaux/fablab_project/venv/lib/python3.11/site-packages/django/core/handlers/base.py", line 313, in resolve_request
    resolver_match = resolver.resolve(request.path_info)
                     ^^^^^^^^^^^^^^^^^^^^^^^^^^^^^^^^^^^
  File "/Users/corentindremaux/fablab_project/venv/lib/python3.11/site-packages/django/urls/resolvers.py", line 705, in resolve
    raise Resolver404({"tried": tried, "path": new_path})
django.urls.exceptions.Resolver404: {'tried': [[<URLResolver <URLPattern list> (admin:admin) 'admin/'>], [<URLResolver <URLPattern list> (None:None) 'api/'>, <URLPattern '^produits/$' [name='produit-list']>], [<URLResolver <URLPattern list> (None:None) 'api/'>, <URLPattern '^produits\.(?P<format>[a-z0-9]+)/?$' [name='produit-list']>], [<URLResolver <URLPattern list> (None:None) 'api/'>, <URLPattern '^produits/(?P<pk>[^/.]+)/$' [name='produit-detail']>], [<URLResolver <URLPattern list> (None:None) 'api/'>, <URLPattern '^produits/(?P<pk>[^/.]+)\.(?P<format>[a-z0-9]+)/?$' [name='produit-detail']>], [<URLResolver <URLPattern list> (None:None) 'api/'>, <URLPattern '^sandwiches/$' [name='sandwich-list']>], [<URLResolver <URLPattern list> (None:None) 'api/'>, <URLPattern '^sandwiches\.(?P<format>[a-z0-9]+)/?$' [name='sandwich-list']>], [<URLResolver <URLPattern list> (None:None) 'api/'>, <URLPattern '^sandwiches/(?P<pk>[^/.]+)/$' [name='sandwich-detail']>], [<URLResolver <URLPattern list> (None:None) 'api/'>, <URLPattern '^sandwiches/(?P<pk>[^/.]+)\.(?P<format>[a-z0-9]+)/?$' [name='sandwich-detail']>], [<URLResolver <URLPattern list> (None:None) 'api/'>, <URLPattern '^commandes/$' [name='commande-list']>], [<URLResolver <URLPattern list> (None:None) 'api/'>, <URLPattern '^commandes\.(?P<format>[a-z0-9]+)/?$' [name='commande-list']>], [<URLResolver <URLPattern list> (None:None) 'api/'>, <URLPattern '^commandes/(?P<pk>[^/.]+)/$' [name='commande-detail']>], [<URLResolver <URLPattern list> (None:None) 'api/'>, <URLPattern '^commandes/(?P<pk>[^/.]+)\.(?P<format>[a-z0-9]+)/?$' [name='commande-detail']>], [<URLResolver <URLPattern list> (None:None) 'api/'>, <URLPattern '^commandes/(?P<pk>[^/.]+)/changer_statut/$' [name='commande-changer-statut']>], [<URLResolver <URLPattern list> (None:None) 'api/'>, <URLPattern '^commandes/(?P<pk>[^/.]+)/changer_statut\.(?P<format>[a-z0-9]+)/?$' [name='commande-changer-statut']>], [<URLResolver <URLPattern list> (None:None) 'api/'>, <URLPattern '' [name='api-root']>], [<URLResolver <URLPattern list> (None:None) 'api/'>, <URLPattern '<drf_format_suffix:format>' [name='api-root']>], [<URLPattern 'api/stock/' [name='stock']>], [<URLPattern '^static/(?P<path>.*)$'>]], 'path': 'api/commandes'}

During handling of the above exception, another exception occurred:

Traceback (most recent call last):
  File "/Users/corentindremaux/fablab_project/venv/lib/python3.11/site-packages/django/template/base.py", line 883, in _resolve_lookup
    current = current[bit]
              ~~~~~~~^^^^^
TypeError: 'URLResolver' object is not subscriptable

During handling of the above exception, another exception occurred:

Traceback (most recent call last):
  File "/Users/corentindremaux/fablab_project/venv/lib/python3.11/site-packages/django/template/base.py", line 893, in _resolve_lookup
    current = getattr(current, bit)
              ^^^^^^^^^^^^^^^^^^^^^
AttributeError: 'URLResolver' object has no attribute 'name'

During handling of the above exception, another exception occurred:

Traceback (most recent call last):
  File "/Users/corentindremaux/fablab_project/venv/lib/python3.11/site-packages/django/template/base.py", line 899, in _resolve_lookup
    current = current[int(bit)]
                      ^^^^^^^^
ValueError: invalid literal for int() with base 10: 'name'

During handling of the above exception, another exception occurred:

Traceback (most recent call last):
  File "/Users/corentindremaux/fablab_project/venv/lib/python3.11/site-packages/django/template/base.py", line 906, in _resolve_lookup
    raise VariableDoesNotExist(
django.template.base.VariableDoesNotExist: Failed lookup for key [name] in <URLResolver <URLPattern list> (admin:admin) 'admin/'>
2025-01-28 11:55:14,996 [DEBUG] utils: (0.000) SELECT "django_session"."session_key", "django_session"."session_data", "django_session"."expire_date" FROM "django_session" WHERE ("django_session"."expire_date" > '2025-01-28 11:55:14.994642' AND "django_session"."session_key" = 'fwpq37u49j36oj3xtwrkhy7bf34wzur2') LIMIT 21; args=('2025-01-28 11:55:14.994642', 'fwpq37u49j36oj3xtwrkhy7bf34wzur2'); alias=default
2025-01-28 11:55:14,997 [DEBUG] utils: (0.000) SELECT "auth_user"."id", "auth_user"."password", "auth_user"."last_login", "auth_user"."is_superuser", "auth_user"."username", "auth_user"."first_name", "auth_user"."last_name", "auth_user"."email", "auth_user"."is_staff", "auth_user"."is_active", "auth_user"."date_joined" FROM "auth_user" WHERE "auth_user"."id" = 1 LIMIT 21; args=(1,); alias=default
2025-01-28 11:55:14,997 [DEBUG] utils: (0.000) SELECT "commandes_commande"."id", "commandes_commande"."sandwich_id", "commandes_commande"."quantite", "commandes_commande"."poids_total", "commandes_commande"."temps_cuisson_total", "commandes_commande"."status", "commandes_commande"."code_barre", "commandes_commande"."date_commande" FROM "commandes_commande"; args=(); alias=default
2025-01-28 11:55:15,000 [DEBUG] utils: (0.000) SELECT "commandes_sandwich"."id", "commandes_sandwich"."nom", "commandes_sandwich"."taille", "commandes_sandwich"."poids_total", "commandes_sandwich"."temps_cuisson" FROM "commandes_sandwich" WHERE "commandes_sandwich"."id" = 1 LIMIT 21; args=(1,); alias=default
2025-01-28 11:55:15,002 [DEBUG] utils: (0.000) SELECT "commandes_produit"."id", "commandes_produit"."nom", "commandes_produit"."taille", "commandes_produit"."poids", "commandes_produit"."quantite_stock", "commandes_produit"."couleur", "commandes_produit"."temps_cuisson" FROM "commandes_produit" INNER JOIN "commandes_sandwich_produits" ON ("commandes_produit"."id" = "commandes_sandwich_produits"."produit_id") WHERE "commandes_sandwich_produits"."sandwich_id" = 1; args=(1,); alias=default
2025-01-28 11:55:15,003 [DEBUG] utils: (0.000) SELECT "commandes_sandwich"."id", "commandes_sandwich"."nom", "commandes_sandwich"."taille", "commandes_sandwich"."poids_total", "commandes_sandwich"."temps_cuisson" FROM "commandes_sandwich" WHERE "commandes_sandwich"."id" = 1 LIMIT 21; args=(1,); alias=default
2025-01-28 11:55:15,004 [DEBUG] utils: (0.000) SELECT "commandes_produit"."id", "commandes_produit"."nom", "commandes_produit"."taille", "commandes_produit"."poids", "commandes_produit"."quantite_stock", "commandes_produit"."couleur", "commandes_produit"."temps_cuisson" FROM "commandes_produit" INNER JOIN "commandes_sandwich_produits" ON ("commandes_produit"."id" = "commandes_sandwich_produits"."produit_id") WHERE "commandes_sandwich_produits"."sandwich_id" = 1; args=(1,); alias=default
2025-01-28 11:55:15,012 [DEBUG] base: Exception while resolving variable 'hide_label' in template 'rest_framework/horizontal/input.html'.
Traceback (most recent call last):
  File "/Users/corentindremaux/fablab_project/venv/lib/python3.11/site-packages/django/template/base.py", line 883, in _resolve_lookup
    current = current[bit]
              ~~~~~~~^^^^^
KeyError: 'hide_label'

During handling of the above exception, another exception occurred:

Traceback (most recent call last):
  File "/Users/corentindremaux/fablab_project/venv/lib/python3.11/site-packages/django/template/base.py", line 893, in _resolve_lookup
    current = getattr(current, bit)
              ^^^^^^^^^^^^^^^^^^^^^
AttributeError: 'dict' object has no attribute 'hide_label'

During handling of the above exception, another exception occurred:

Traceback (most recent call last):
  File "/Users/corentindremaux/fablab_project/venv/lib/python3.11/site-packages/django/template/base.py", line 899, in _resolve_lookup
    current = current[int(bit)]
                      ^^^^^^^^
ValueError: invalid literal for int() with base 10: 'hide_label'

During handling of the above exception, another exception occurred:

Traceback (most recent call last):
  File "/Users/corentindremaux/fablab_project/venv/lib/python3.11/site-packages/django/template/base.py", line 906, in _resolve_lookup
    raise VariableDoesNotExist(
django.template.base.VariableDoesNotExist: Failed lookup for key [hide_label] in {'base_template': 'input.html', 'input_type': 'number', 'template_pack': 'rest_framework/horizontal', 'renderer': <rest_framework.renderers.HTMLFormRenderer object at 0x10f368f10>}
2025-01-28 11:55:15,013 [DEBUG] base: Exception while resolving variable 'placeholder' in template 'rest_framework/horizontal/input.html'.
Traceback (most recent call last):
  File "/Users/corentindremaux/fablab_project/venv/lib/python3.11/site-packages/django/template/base.py", line 883, in _resolve_lookup
    current = current[bit]
              ~~~~~~~^^^^^
KeyError: 'placeholder'

During handling of the above exception, another exception occurred:

Traceback (most recent call last):
  File "/Users/corentindremaux/fablab_project/venv/lib/python3.11/site-packages/django/template/base.py", line 893, in _resolve_lookup
    current = getattr(current, bit)
              ^^^^^^^^^^^^^^^^^^^^^
AttributeError: 'dict' object has no attribute 'placeholder'

During handling of the above exception, another exception occurred:

Traceback (most recent call last):
  File "/Users/corentindremaux/fablab_project/venv/lib/python3.11/site-packages/django/template/base.py", line 899, in _resolve_lookup
    current = current[int(bit)]
                      ^^^^^^^^
ValueError: invalid literal for int() with base 10: 'placeholder'

During handling of the above exception, another exception occurred:

Traceback (most recent call last):
  File "/Users/corentindremaux/fablab_project/venv/lib/python3.11/site-packages/django/template/base.py", line 906, in _resolve_lookup
    raise VariableDoesNotExist(
django.template.base.VariableDoesNotExist: Failed lookup for key [placeholder] in {'base_template': 'input.html', 'input_type': 'number', 'template_pack': 'rest_framework/horizontal', 'renderer': <rest_framework.renderers.HTMLFormRenderer object at 0x10f368f10>}
2025-01-28 11:55:15,014 [DEBUG] base: Exception while resolving variable 'autofocus' in template 'rest_framework/horizontal/input.html'.
Traceback (most recent call last):
  File "/Users/corentindremaux/fablab_project/venv/lib/python3.11/site-packages/django/template/base.py", line 883, in _resolve_lookup
    current = current[bit]
              ~~~~~~~^^^^^
KeyError: 'autofocus'

During handling of the above exception, another exception occurred:

Traceback (most recent call last):
  File "/Users/corentindremaux/fablab_project/venv/lib/python3.11/site-packages/django/template/base.py", line 893, in _resolve_lookup
    current = getattr(current, bit)
              ^^^^^^^^^^^^^^^^^^^^^
AttributeError: 'dict' object has no attribute 'autofocus'

During handling of the above exception, another exception occurred:

Traceback (most recent call last):
  File "/Users/corentindremaux/fablab_project/venv/lib/python3.11/site-packages/django/template/base.py", line 899, in _resolve_lookup
    current = current[int(bit)]
                      ^^^^^^^^
ValueError: invalid literal for int() with base 10: 'autofocus'

During handling of the above exception, another exception occurred:

Traceback (most recent call last):
  File "/Users/corentindremaux/fablab_project/venv/lib/python3.11/site-packages/django/template/base.py", line 906, in _resolve_lookup
    raise VariableDoesNotExist(
django.template.base.VariableDoesNotExist: Failed lookup for key [autofocus] in {'base_template': 'input.html', 'input_type': 'number', 'template_pack': 'rest_framework/horizontal', 'renderer': <rest_framework.renderers.HTMLFormRenderer object at 0x10f368f10>}
2025-01-28 11:55:15,015 [DEBUG] base: Exception while resolving variable 'hide_label' in template 'rest_framework/horizontal/input.html'.
Traceback (most recent call last):
  File "/Users/corentindremaux/fablab_project/venv/lib/python3.11/site-packages/django/template/base.py", line 883, in _resolve_lookup
    current = current[bit]
              ~~~~~~~^^^^^
KeyError: 'hide_label'

During handling of the above exception, another exception occurred:

Traceback (most recent call last):
  File "/Users/corentindremaux/fablab_project/venv/lib/python3.11/site-packages/django/template/base.py", line 893, in _resolve_lookup
    current = getattr(current, bit)
              ^^^^^^^^^^^^^^^^^^^^^
AttributeError: 'dict' object has no attribute 'hide_label'

During handling of the above exception, another exception occurred:

Traceback (most recent call last):
  File "/Users/corentindremaux/fablab_project/venv/lib/python3.11/site-packages/django/template/base.py", line 899, in _resolve_lookup
    current = current[int(bit)]
                      ^^^^^^^^
ValueError: invalid literal for int() with base 10: 'hide_label'

During handling of the above exception, another exception occurred:

Traceback (most recent call last):
  File "/Users/corentindremaux/fablab_project/venv/lib/python3.11/site-packages/django/template/base.py", line 906, in _resolve_lookup
    raise VariableDoesNotExist(
django.template.base.VariableDoesNotExist: Failed lookup for key [hide_label] in {'base_template': 'input.html', 'input_type': 'number', 'template_pack': 'rest_framework/horizontal', 'renderer': <rest_framework.renderers.HTMLFormRenderer object at 0x10f368f10>}
2025-01-28 11:55:15,016 [DEBUG] base: Exception while resolving variable 'placeholder' in template 'rest_framework/horizontal/input.html'.
Traceback (most recent call last):
  File "/Users/corentindremaux/fablab_project/venv/lib/python3.11/site-packages/django/template/base.py", line 883, in _resolve_lookup
    current = current[bit]
              ~~~~~~~^^^^^
KeyError: 'placeholder'

During handling of the above exception, another exception occurred:

Traceback (most recent call last):
  File "/Users/corentindremaux/fablab_project/venv/lib/python3.11/site-packages/django/template/base.py", line 893, in _resolve_lookup
    current = getattr(current, bit)
              ^^^^^^^^^^^^^^^^^^^^^
AttributeError: 'dict' object has no attribute 'placeholder'

During handling of the above exception, another exception occurred:

Traceback (most recent call last):
  File "/Users/corentindremaux/fablab_project/venv/lib/python3.11/site-packages/django/template/base.py", line 899, in _resolve_lookup
    current = current[int(bit)]
                      ^^^^^^^^
ValueError: invalid literal for int() with base 10: 'placeholder'

During handling of the above exception, another exception occurred:

Traceback (most recent call last):
  File "/Users/corentindremaux/fablab_project/venv/lib/python3.11/site-packages/django/template/base.py", line 906, in _resolve_lookup
    raise VariableDoesNotExist(
django.template.base.VariableDoesNotExist: Failed lookup for key [placeholder] in {'base_template': 'input.html', 'input_type': 'number', 'template_pack': 'rest_framework/horizontal', 'renderer': <rest_framework.renderers.HTMLFormRenderer object at 0x10f368f10>}
2025-01-28 11:55:15,017 [DEBUG] base: Exception while resolving variable 'autofocus' in template 'rest_framework/horizontal/input.html'.
Traceback (most recent call last):
  File "/Users/corentindremaux/fablab_project/venv/lib/python3.11/site-packages/django/template/base.py", line 883, in _resolve_lookup
    current = current[bit]
              ~~~~~~~^^^^^
KeyError: 'autofocus'

During handling of the above exception, another exception occurred:

Traceback (most recent call last):
  File "/Users/corentindremaux/fablab_project/venv/lib/python3.11/site-packages/django/template/base.py", line 893, in _resolve_lookup
    current = getattr(current, bit)
              ^^^^^^^^^^^^^^^^^^^^^
AttributeError: 'dict' object has no attribute 'autofocus'

During handling of the above exception, another exception occurred:

Traceback (most recent call last):
  File "/Users/corentindremaux/fablab_project/venv/lib/python3.11/site-packages/django/template/base.py", line 899, in _resolve_lookup
    current = current[int(bit)]
                      ^^^^^^^^
ValueError: invalid literal for int() with base 10: 'autofocus'

During handling of the above exception, another exception occurred:

Traceback (most recent call last):
  File "/Users/corentindremaux/fablab_project/venv/lib/python3.11/site-packages/django/template/base.py", line 906, in _resolve_lookup
    raise VariableDoesNotExist(
django.template.base.VariableDoesNotExist: Failed lookup for key [autofocus] in {'base_template': 'input.html', 'input_type': 'number', 'template_pack': 'rest_framework/horizontal', 'renderer': <rest_framework.renderers.HTMLFormRenderer object at 0x10f368f10>}
2025-01-28 11:55:15,018 [DEBUG] base: Exception while resolving variable 'hide_label' in template 'rest_framework/horizontal/input.html'.
Traceback (most recent call last):
  File "/Users/corentindremaux/fablab_project/venv/lib/python3.11/site-packages/django/template/base.py", line 883, in _resolve_lookup
    current = current[bit]
              ~~~~~~~^^^^^
KeyError: 'hide_label'

During handling of the above exception, another exception occurred:

Traceback (most recent call last):
  File "/Users/corentindremaux/fablab_project/venv/lib/python3.11/site-packages/django/template/base.py", line 893, in _resolve_lookup
    current = getattr(current, bit)
              ^^^^^^^^^^^^^^^^^^^^^
AttributeError: 'dict' object has no attribute 'hide_label'

During handling of the above exception, another exception occurred:

Traceback (most recent call last):
  File "/Users/corentindremaux/fablab_project/venv/lib/python3.11/site-packages/django/template/base.py", line 899, in _resolve_lookup
    current = current[int(bit)]
                      ^^^^^^^^
ValueError: invalid literal for int() with base 10: 'hide_label'

During handling of the above exception, another exception occurred:

Traceback (most recent call last):
  File "/Users/corentindremaux/fablab_project/venv/lib/python3.11/site-packages/django/template/base.py", line 906, in _resolve_lookup
    raise VariableDoesNotExist(
django.template.base.VariableDoesNotExist: Failed lookup for key [hide_label] in {'base_template': 'input.html', 'input_type': 'number', 'template_pack': 'rest_framework/horizontal', 'renderer': <rest_framework.renderers.HTMLFormRenderer object at 0x10f368f10>}
2025-01-28 11:55:15,018 [DEBUG] base: Exception while resolving variable 'placeholder' in template 'rest_framework/horizontal/input.html'.
Traceback (most recent call last):
  File "/Users/corentindremaux/fablab_project/venv/lib/python3.11/site-packages/django/template/base.py", line 883, in _resolve_lookup
    current = current[bit]
              ~~~~~~~^^^^^
KeyError: 'placeholder'

During handling of the above exception, another exception occurred:

Traceback (most recent call last):
  File "/Users/corentindremaux/fablab_project/venv/lib/python3.11/site-packages/django/template/base.py", line 893, in _resolve_lookup
    current = getattr(current, bit)
              ^^^^^^^^^^^^^^^^^^^^^
AttributeError: 'dict' object has no attribute 'placeholder'

During handling of the above exception, another exception occurred:

Traceback (most recent call last):
  File "/Users/corentindremaux/fablab_project/venv/lib/python3.11/site-packages/django/template/base.py", line 899, in _resolve_lookup
    current = current[int(bit)]
                      ^^^^^^^^
ValueError: invalid literal for int() with base 10: 'placeholder'

During handling of the above exception, another exception occurred:

Traceback (most recent call last):
  File "/Users/corentindremaux/fablab_project/venv/lib/python3.11/site-packages/django/template/base.py", line 906, in _resolve_lookup
    raise VariableDoesNotExist(
django.template.base.VariableDoesNotExist: Failed lookup for key [placeholder] in {'base_template': 'input.html', 'input_type': 'number', 'template_pack': 'rest_framework/horizontal', 'renderer': <rest_framework.renderers.HTMLFormRenderer object at 0x10f368f10>}
2025-01-28 11:55:15,019 [DEBUG] base: Exception while resolving variable 'autofocus' in template 'rest_framework/horizontal/input.html'.
Traceback (most recent call last):
  File "/Users/corentindremaux/fablab_project/venv/lib/python3.11/site-packages/django/template/base.py", line 883, in _resolve_lookup
    current = current[bit]
              ~~~~~~~^^^^^
KeyError: 'autofocus'

During handling of the above exception, another exception occurred:

Traceback (most recent call last):
  File "/Users/corentindremaux/fablab_project/venv/lib/python3.11/site-packages/django/template/base.py", line 893, in _resolve_lookup
    current = getattr(current, bit)
              ^^^^^^^^^^^^^^^^^^^^^
AttributeError: 'dict' object has no attribute 'autofocus'

During handling of the above exception, another exception occurred:

Traceback (most recent call last):
  File "/Users/corentindremaux/fablab_project/venv/lib/python3.11/site-packages/django/template/base.py", line 899, in _resolve_lookup
    current = current[int(bit)]
                      ^^^^^^^^
ValueError: invalid literal for int() with base 10: 'autofocus'

During handling of the above exception, another exception occurred:

Traceback (most recent call last):
  File "/Users/corentindremaux/fablab_project/venv/lib/python3.11/site-packages/django/template/base.py", line 906, in _resolve_lookup
    raise VariableDoesNotExist(
django.template.base.VariableDoesNotExist: Failed lookup for key [autofocus] in {'base_template': 'input.html', 'input_type': 'number', 'template_pack': 'rest_framework/horizontal', 'renderer': <rest_framework.renderers.HTMLFormRenderer object at 0x10f368f10>}
2025-01-28 11:55:15,021 [DEBUG] base: Exception while resolving variable 'hide_label' in template 'rest_framework/horizontal/select.html'.
Traceback (most recent call last):
  File "/Users/corentindremaux/fablab_project/venv/lib/python3.11/site-packages/django/template/base.py", line 883, in _resolve_lookup
    current = current[bit]
              ~~~~~~~^^^^^
KeyError: 'hide_label'

During handling of the above exception, another exception occurred:

Traceback (most recent call last):
  File "/Users/corentindremaux/fablab_project/venv/lib/python3.11/site-packages/django/template/base.py", line 893, in _resolve_lookup
    current = getattr(current, bit)
              ^^^^^^^^^^^^^^^^^^^^^
AttributeError: 'dict' object has no attribute 'hide_label'

During handling of the above exception, another exception occurred:

Traceback (most recent call last):
  File "/Users/corentindremaux/fablab_project/venv/lib/python3.11/site-packages/django/template/base.py", line 899, in _resolve_lookup
    current = current[int(bit)]
                      ^^^^^^^^
ValueError: invalid literal for int() with base 10: 'hide_label'

During handling of the above exception, another exception occurred:

Traceback (most recent call last):
  File "/Users/corentindremaux/fablab_project/venv/lib/python3.11/site-packages/django/template/base.py", line 906, in _resolve_lookup
    raise VariableDoesNotExist(
django.template.base.VariableDoesNotExist: Failed lookup for key [hide_label] in {'base_template': 'select.html', 'template_pack': 'rest_framework/horizontal', 'renderer': <rest_framework.renderers.HTMLFormRenderer object at 0x10f368f10>}
2025-01-28 11:55:21,652 [DEBUG] base: Exception while resolving variable 'name' in template 'unknown'.
Traceback (most recent call last):
  File "/Users/corentindremaux/fablab_project/venv/lib/python3.11/site-packages/asgiref/sync.py", line 518, in thread_handler
    raise exc_info[1]
  File "/Users/corentindremaux/fablab_project/venv/lib/python3.11/site-packages/django/core/handlers/exception.py", line 42, in inner
    response = await get_response(request)
               ^^^^^^^^^^^^^^^^^^^^^^^^^^^
  File "/Users/corentindremaux/fablab_project/venv/lib/python3.11/site-packages/django/core/handlers/base.py", line 235, in _get_response_async
    callback, callback_args, callback_kwargs = self.resolve_request(request)
                                               ^^^^^^^^^^^^^^^^^^^^^^^^^^^^^
  File "/Users/corentindremaux/fablab_project/venv/lib/python3.11/site-packages/django/core/handlers/base.py", line 313, in resolve_request
    resolver_match = resolver.resolve(request.path_info)
                     ^^^^^^^^^^^^^^^^^^^^^^^^^^^^^^^^^^^
  File "/Users/corentindremaux/fablab_project/venv/lib/python3.11/site-packages/django/urls/resolvers.py", line 705, in resolve
    raise Resolver404({"tried": tried, "path": new_path})
django.urls.exceptions.Resolver404: {'tried': [[<URLResolver <URLPattern list> (admin:admin) 'admin/'>], [<URLResolver <URLPattern list> (None:None) 'api/'>, <URLPattern '^produits/$' [name='produit-list']>], [<URLResolver <URLPattern list> (None:None) 'api/'>, <URLPattern '^produits\.(?P<format>[a-z0-9]+)/?$' [name='produit-list']>], [<URLResolver <URLPattern list> (None:None) 'api/'>, <URLPattern '^produits/(?P<pk>[^/.]+)/$' [name='produit-detail']>], [<URLResolver <URLPattern list> (None:None) 'api/'>, <URLPattern '^produits/(?P<pk>[^/.]+)\.(?P<format>[a-z0-9]+)/?$' [name='produit-detail']>], [<URLResolver <URLPattern list> (None:None) 'api/'>, <URLPattern '^sandwiches/$' [name='sandwich-list']>], [<URLResolver <URLPattern list> (None:None) 'api/'>, <URLPattern '^sandwiches\.(?P<format>[a-z0-9]+)/?$' [name='sandwich-list']>], [<URLResolver <URLPattern list> (None:None) 'api/'>, <URLPattern '^sandwiches/(?P<pk>[^/.]+)/$' [name='sandwich-detail']>], [<URLResolver <URLPattern list> (None:None) 'api/'>, <URLPattern '^sandwiches/(?P<pk>[^/.]+)\.(?P<format>[a-z0-9]+)/?$' [name='sandwich-detail']>], [<URLResolver <URLPattern list> (None:None) 'api/'>, <URLPattern '^commandes/$' [name='commande-list']>], [<URLResolver <URLPattern list> (None:None) 'api/'>, <URLPattern '^commandes\.(?P<format>[a-z0-9]+)/?$' [name='commande-list']>], [<URLResolver <URLPattern list> (None:None) 'api/'>, <URLPattern '^commandes/(?P<pk>[^/.]+)/$' [name='commande-detail']>], [<URLResolver <URLPattern list> (None:None) 'api/'>, <URLPattern '^commandes/(?P<pk>[^/.]+)\.(?P<format>[a-z0-9]+)/?$' [name='commande-detail']>], [<URLResolver <URLPattern list> (None:None) 'api/'>, <URLPattern '^commandes/(?P<pk>[^/.]+)/changer_statut/$' [name='commande-changer-statut']>], [<URLResolver <URLPattern list> (None:None) 'api/'>, <URLPattern '^commandes/(?P<pk>[^/.]+)/changer_statut\.(?P<format>[a-z0-9]+)/?$' [name='commande-changer-statut']>], [<URLResolver <URLPattern list> (None:None) 'api/'>, <URLPattern '' [name='api-root']>], [<URLResolver <URLPattern list> (None:None) 'api/'>, <URLPattern '<drf_format_suffix:format>' [name='api-root']>], [<URLPattern 'api/stock/' [name='stock']>], [<URLPattern '^static/(?P<path>.*)$'>]], 'path': 'api/stock'}

During handling of the above exception, another exception occurred:

Traceback (most recent call last):
  File "/Users/corentindremaux/fablab_project/venv/lib/python3.11/site-packages/django/template/base.py", line 883, in _resolve_lookup
    current = current[bit]
              ~~~~~~~^^^^^
TypeError: 'URLResolver' object is not subscriptable

During handling of the above exception, another exception occurred:

Traceback (most recent call last):
  File "/Users/corentindremaux/fablab_project/venv/lib/python3.11/site-packages/django/template/base.py", line 893, in _resolve_lookup
    current = getattr(current, bit)
              ^^^^^^^^^^^^^^^^^^^^^
AttributeError: 'URLResolver' object has no attribute 'name'

During handling of the above exception, another exception occurred:

Traceback (most recent call last):
  File "/Users/corentindremaux/fablab_project/venv/lib/python3.11/site-packages/django/template/base.py", line 899, in _resolve_lookup
    current = current[int(bit)]
                      ^^^^^^^^
ValueError: invalid literal for int() with base 10: 'name'

During handling of the above exception, another exception occurred:

Traceback (most recent call last):
  File "/Users/corentindremaux/fablab_project/venv/lib/python3.11/site-packages/django/template/base.py", line 906, in _resolve_lookup
    raise VariableDoesNotExist(
django.template.base.VariableDoesNotExist: Failed lookup for key [name] in <URLResolver <URLPattern list> (admin:admin) 'admin/'>
2025-01-28 11:55:21,665 [DEBUG] utils: (0.000) SELECT "django_session"."session_key", "django_session"."session_data", "django_session"."expire_date" FROM "django_session" WHERE ("django_session"."expire_date" > '2025-01-28 11:55:21.664558' AND "django_session"."session_key" = 'fwpq37u49j36oj3xtwrkhy7bf34wzur2') LIMIT 21; args=('2025-01-28 11:55:21.664558', 'fwpq37u49j36oj3xtwrkhy7bf34wzur2'); alias=default
2025-01-28 11:55:21,666 [DEBUG] utils: (0.000) SELECT "auth_user"."id", "auth_user"."password", "auth_user"."last_login", "auth_user"."is_superuser", "auth_user"."username", "auth_user"."first_name", "auth_user"."last_name", "auth_user"."email", "auth_user"."is_staff", "auth_user"."is_active", "auth_user"."date_joined" FROM "auth_user" WHERE "auth_user"."id" = 1 LIMIT 21; args=(1,); alias=default
2025-01-28 11:55:21,667 [DEBUG] utils: (0.000) SELECT "commandes_produit"."id", "commandes_produit"."nom", "commandes_produit"."taille", "commandes_produit"."poids", "commandes_produit"."quantite_stock", "commandes_produit"."couleur", "commandes_produit"."temps_cuisson" FROM "commandes_produit"; args=(); alias=default
2025-01-28 11:58:17,619 [DEBUG] base: Asynchronous handler adapted for middleware whitenoise.middleware.WhiteNoiseMiddleware.
